Workbook

Sheet Overview
B1: Trading Assignment
A3: x | B3: Overview
B5: Buying Power | F5: Margin | J5: P/L
B6: Assumptions | F6: Summary Pt. 1 | J6: Summary Pt. 1
B7: Starting Buying Power | D7: 200000000 | F7: All figures are related to initial balance req. | J7: Total P/L | L7: =SUM(J34:J45) -> 21855038
B8: Buying Power Pt. 1 | D8: =D7/2 -> 100000000 | F8: Total Initial Margin | H8: =SUM(H34:H45) -> 82891470
B9: Buying Power Pt. 2 | D9: =D8 -> 100000000 | F9: Total Maintenance Margin | H9: =SUM(I34:I45) -> 70330176
B11: Balances | F11: Summary Pt. 2 | J11: Summary Pt. 1
B12: Net Cash Balance Pt. 1 | D12: =SUMIF(K34:K45,"Opened*",G34:G45)+SUMIF(K34:K45, "Closed*", F34:F45) -> 1.3153308e+08 | F12: All figures are related to initial balance req. | J12: Total P/L | L12: =SUM(J20:J30) -> 3608491
B13: Net Cash Balance Pt. 2 | D13: =D9+SUM(J20:J30) -> 103608491 | F13: Total Margin Initally | H13: =SUM(H20:H30) -> 50092180
B14: Active Margin Balance Pt. 1 | D14: =SUMIF(K34:K45,"Opened*", G34:G45) -> 0
B15: Active Margin Balance Pt. 2 | D15: 0
B17: Part 2 | G17: Net Trade Costs
B18: Breakdown | D18: Symbol | E18: Options Strategy | G18: (Debit & Credit) | H18: Margin | J18: Profit or Loss | K18: Status
B19: Options Strat. 1
B20: 1. TSLA | D20: CX64 & CGW | E20: CALENDAR SPREAD | G20: =STRAT1_TSLA!D23+STRAT1_TSLA!E23 -> 138400 | H20: =STRAT1_TSLA!E25 -> 12511840 | J20: =STRAT1_TSLA!F20 -> 765600 | K20: Closed 18-Nov
B21: 2. DJT | D21: C7KL & C20C | E21: CALENDAR SPREAD | G21: =STRAT1_DJT!D23+STRAT1_DJT!E23 -> 1864000 | H21: =STRAT1_DJT!E25 -> 11438400 | J21: =STRAT1_DJT!F20 -> 1176000 | K21: Closed 18-Nov
B22: 3. YUM | D22: =STRAT1_YUM!D13&" & "&STRAT1_YUM!E13 -> CVW & CLCC | E22: CALENDAR SPREAD | G22: =STRAT1_YUM!D23+STRAT1_YUM!E23 -> 144800 | H22: =STRAT1_YUM!E25 -> 8785440 | J22: =STRAT1_YUM!F20 -> 123200 | K22: Closed 12-Nov
B23: Options Strat. 2
B24: 1. XOM | D24: =STRAT2_XOM!D13&" & "&STRAT2_XOM!E13 -> PP3Q & P29F | E24: BEAR SPREAD | G24: =STRAT2_XOM!D23+STRAT2_XOM!E23 -> 506000 | H24: =STRAT2_XOM!E25 -> 4364000 | J24: =STRAT2_XOM!F20 -> -106000 | K24: Closed 27-Nov
B25: 2. CVX | D25: =STRAT2_CVX!D13&" & "&STRAT2_CVX!E13 -> P9Q & PW1 | E25: BEAR SPREAD | G25: =STRAT2_CVX!D23+STRAT2_CVX!E23 -> 655000 | H25: =STRAT2_CVX!E25 -> 8013500 | J25: =STRAT2_CVX!F20 -> 185000 | K25: Closed 12-Nov
B26: 3. OXY | D26: =STRAT2_OXY!D13&" & "&STRAT2_OXY!E13 -> PTV9 & PW8 | E26: BEAR SPREAD | G26: =STRAT2_OXY!D23+STRAT2_OXY!E23 -> 455000 | H26: =STRAT2_OXY!E25 -> 4979000 | J26: =STRAT2_OXY!F20 -> 170000 | K26: Closed 27-Nov
B27: Options Strat. 3
B28: 1. JPM | D28: =STRAT3_JPM!D13&" & "&STRAT3_JPM!E13 -> JPM & P0RG | E28: PROTECTIVE PUT | G28: =STRAT3_JPM!D23+STRAT3_JPM!E23 -> 12095090 | H28: 0 | J28: =STRAT3_JPM!F20 -> 394555 | K28: Closed 27-Nov
B29: 2. WFC | D29: =STRAT3_WFC!D13&" & "&STRAT3_WFC!E13 -> WFC & P6X4 | E29: PROTECTIVE PUT | G29: =STRAT3_WFC!D23+STRAT3_WFC!E23 -> 8738328 | H29: 0 | J29: =STRAT3_WFC!F20 -> 527496 | K29: Closed 27-Nov
B30: 3. BAC | D30: =STRAT3_BAC!D13&" & "&STRAT3_BAC!E13 -> BAC & P3Q1 | E30: PROTECTIVE PUT | G30: =STRAT3_BAC!D23+STRAT3_BAC!E23 -> 9182680 | H30: 0 | J30: =STRAT3_BAC!F20 -> 372640 | K30: Closed 27-Nov
A32: x | B32: Breakdown | D32: Symbol | E32: Type | F32: NET Current Account | G32: Total Margin incl. Payments | H32: Intial Margin | I32: Maintenance Margin | J32: Cummulative Profit or Loss | K32: Status
B33: Hedges
B34: 1. Lithium | D34: =H1_Lithium!D10 -> LTHG2025 | E34: =H1_Lithium!D11 -> LONG | F34: {=INDEX(LithiumTable[Curr. after Margin Payments],COUNT(ROW(LithiumTable[])))} -> 4970122.4 | G34: =SUM(LithiumTable[Margin Payment]) -> 7279510.2 | H34: =H1_Lithium!D18 -> 5984000 | I34: =H1_Lithium!D21 -> 4787200 | J34: {=INDEX(LithiumTable[Cum. Total],COUNT(ROW(LithiumTable[])))} -> -2309387.8 | K34: {=IF(IFERROR(VLOOKUP("Exit",LithiumTable[Entry/Exit],1),VLOOKUP("Entry",LithiumTable[Entry/Exit],1))="Entry","Opened "&TEXT(INDEX(LithiumTable[Date],MATCH("Entry",LithiumTable[Entry/Exit])),"dd-mmm"),"Closed "&TEXT(INDEX(LithiumTable[Date],MATCH("Exit",LithiumTable[Entry/Exit])),"dd-mmm"))} -> Closed 26-Nov
B35: 2. Cattle | D35: =H2_Cattle!D9 -> LEZ2024 | E35: =H2_Cattle!D10 -> LONG | F35: {=INDEX(CattleTable[Curr. after Margin Payments],COUNT(ROW(CattleTable[])))} -> 11031250 | G35: =SUM(CattleTable[Margin Payment]) -> 9281250 | H35: =H2_Cattle!D17 -> 7656250 | I35: =H2_Cattle!D20 -> 6125000 | J35: {=INDEX(CattleTable[Cum. Total],COUNT(ROW(CattleTable[])))} -> 1750000 | K35: =IF(IFERROR(VLOOKUP("Exit",CattleTable[Entry/Exit],1),VLOOKUP("Entry",CattleTable[Entry/Exit],1))="Entry","Opened "&TEXT(INDEX(CattleTable[Date],MATCH("Entry",CattleTable[Entry/Exit])),"dd-mmm"),"Closed "&TEXT(INDEX(CattleTable[Date],MATCH("Exit",CattleTable[Entry/Exit])),"dd-mmm")) -> Closed 29-Oct
B36: 3. Soybean | D36: =H3_Soy!D9 -> ZSF5 | E36: =H3_Soy!D10 -> LONG | F36: {=INDEX(SoyTable[Curr. after Margin Payments],COUNT(ROW(SoyTable[])))} -> 17875000 | G36: =SUM(SoyTable[Margin Payment]) -> 9900000 | H36: =H3_Soy!D17 -> 9900000 | I36: =H3_Soy!D20 -> 7920000 | J36: {=INDEX(SoyTable[Cum. Total],COUNT(ROW(SoyTable[])))} -> 7975000 | K36: =IF(IFERROR(VLOOKUP("Exit",SoyTable[Entry/Exit],1),VLOOKUP("Entry",SoyTable[Entry/Exit],1))="Entry","Opened "&TEXT(INDEX(SoyTable[Date],MATCH("Entry",SoyTable[Entry/Exit])),"dd-mmm"),"Closed "&TEXT(INDEX(SoyTable[Date],MATCH("Exit",SoyTable[Entry/Exit])),"dd-mmm")) -> Closed 07-Nov
B37: 4. Heating Oil | D37: =H4_HO!D9 -> HOZ4 | E37: =H4_HO!D10 -> SHORT | F37: {=INDEX(HoTable[Curr. after Margin Payments],COUNT(ROW(HoTable[])))} -> 20668710 | G37: =SUM(HoTable[Margin Payment]) -> 21870284 | H37: =H4_HO!D17 -> 17278220 | I37: =H4_HO!D20 -> 13822576 | J37: {=INDEX(HoTable[Cum. Total],COUNT(ROW(HoTable[])))} -> -1201574.7 | K37: =IF(IFERROR(VLOOKUP("Exit",HoTable[Entry/Exit],1),VLOOKUP("Entry",HoTable[Entry/Exit],1))="Entry","Opened "&TEXT(INDEX(HoTable[Date],MATCH("Entry",HoTable[Entry/Exit])),"dd-mmm"),"Closed "&TEXT(INDEX(HoTable[Date],MATCH("Exit",HoTable[Entry/Exit])),"dd-mmm")) -> Closed 29-Nov
B38: Speculation
B39: 1. Brent WTI | D39: =S1_Brent!D9 -> BZZ4 | E39: =S1_Brent!D10 -> SHORT | F39: {=INDEX(BrentTable[Curr. after Margin Payments],COUNT(ROW(BrentTable[])))} -> 14454000 | G39: =SUM(BrentTable[Margin Payment]) -> 8238000 | H39: =S1_Brent!D17 -> 8238000 | I39: =S1_Brent!D20 -> 6590400 | J39: {=INDEX(BrentTable[Cum. Total],COUNT(ROW(BrentTable[])))} -> 6216000 | K39: =IF(IFERROR(VLOOKUP("Exit",BrentTable[Entry/Exit],1),VLOOKUP("Entry",BrentTable[Entry/Exit],1))="Entry","Opened "&TEXT(INDEX(BrentTable[Date],MATCH("Entry",BrentTable[Entry/Exit])),"dd-mmm"),"Closed "&TEXT(INDEX(BrentTable[Date],MATCH("Exit",BrentTable[Entry/Exit])),"dd-mmm")) -> Closed 16-Oct
B40: 2. Gold | D40: =S2_Gold!D9 -> GCZ4 | E40: =S2_Gold!D10 -> LONG | F40: {=INDEX(GoldTable[Curr. after Margin Payments],COUNT(ROW(GoldTable[])))} -> 18080000 | G40: =SUM(GoldTable[Margin Payment]) -> 13750000 | H40: =S2_Gold!D17 -> 13750000 | I40: =S2_Gold!D21 -> 11000000 | J40: {=INDEX(GoldTable[Cum. Total],COUNT(ROW(GoldTable[])))} -> 4330000 | K40: =IF(IFERROR(VLOOKUP("Exit",GoldTable[Entry/Exit],1),VLOOKUP("Entry",GoldTable[Entry/Exit],1))="Entry","Opened "&TEXT(INDEX(GoldTable[Date],MATCH("Entry",GoldTable[Entry/Exit])),"dd-mmm"),"Closed "&TEXT(INDEX(GoldTable[Date],MATCH("Exit",GoldTable[Entry/Exit])),"dd-mmm")) -> Closed 21-Oct
B41: Stock Options
B42: 1. NVDA | D42: =O1_NVDA!D9 -> CZGP | E42: =O1_NVDA!D10 -> LONG CALL | F42: {=INDEX(NVDATable[Curr. after Margin Payments],COUNT(ROW(NVDATable[])))} -> 9320000 | G42: =SUM(NVDATable[Margin Payment]) -> 4180000 | H42: 0 | I42: 0 | J42: {=INDEX(NVDATable[Cum. Total],COUNT(ROW(NVDATable[])))} -> 5140000 | K42: =IF(IFERROR(VLOOKUP("Exit",NVDATable[Entry/Exit],1),VLOOKUP("Entry",NVDATable[Entry/Exit],1))="Entry","Opened "&TEXT(INDEX(NVDATable[Date],MATCH("Entry",NVDATable[Entry/Exit])),"dd-mmm"),"Closed "&TEXT(INDEX(NVDATable[Date],MATCH("Exit",NVDATable[Entry/Exit])),"dd-mmm")) -> Closed 22-Oct
B43: 2. TLT | D43: =O2_TLT!D9 -> PB7Z | E43: =O2_TLT!D10 -> SHORT PUT | F43: {=INDEX(TltTable[Curr. after Margin Payments],COUNT(ROW(TltTable[])))} -> 12141000 | G43: =SUM(TltTable[Margin Payment]) -> 10911000 | H43: =O2_TLT!D19 -> 10911000 | I43: =H43 -> 10911000 | J43: {=INDEX(TltTable[Cum. Total],COUNT(ROW(TltTable[])))} -> 1230000 | K43: =IF(IFERROR(VLOOKUP("Exit",TltTable[Entry/Exit],1),VLOOKUP("Entry",TltTable[Entry/Exit],1))="Entry","Opened "&TEXT(INDEX(TltTable[Date],MATCH("Entry",TltTable[Entry/Exit])),"dd-mmm"),"Closed "&TEXT(INDEX(TltTable[Date],MATCH("Exit",TltTable[Entry/Exit])),"dd-mmm")) -> Closed 02-Nov
B44: 3. HOOD | D44: =O3_HOOD!D9 -> PY03 | E44: =O3_HOOD!D10 -> LONG PUT | F44: {=INDEX(HOODTable[Curr. after Margin Payments],COUNT(ROW(HOODTable[])))} -> 4480000 | G44: =SUM(HOODTable[Margin Payment]) -> 5920000 | H44: 0 | I44: 0 | J44: {=INDEX(HOODTable[Cum. Total],COUNT(ROW(HOODTable[])))} -> -1440000 | K44: =IF(IFERROR(VLOOKUP("Exit",HOODTable[Entry/Exit],1),VLOOKUP("Entry",HOODTable[Entry/Exit],1))="Entry","Opened "&TEXT(INDEX(HOODTable[Date],MATCH("Entry",HOODTable[Entry/Exit])),"dd-mmm"),"Closed "&TEXT(INDEX(HOODTable[Date],MATCH("Exit",HOODTable[Entry/Exit])),"dd-mmm")) -> Closed 28-Oct
B45: 4. INTC | D45: =O4_INTC!D9 -> PK5N | E45: =O4_INTC!D10 -> SHORT PUT | F45: {=INDEX(INTCTable[Curr. after Margin Payments],COUNT(ROW(INTCTable[])))} -> 18513000 | G45: =SUM(INTCTable[Margin Payment]) -> 18348000 | H45: =O4_INTC!D19 -> 9174000 | I45: =H45 -> 9174000 | J45: {=INDEX(INTCTable[Cum. Total],COUNT(ROW(INTCTable[])))} -> 165000 | K45: =IF(IFERROR(VLOOKUP("Exit",INTCTable[Entry/Exit],1),VLOOKUP("Entry",INTCTable[Entry/Exit],1))="Entry","Opened "&TEXT(INDEX(INTCTable[Date],MATCH("Entry",INTCTable[Entry/Exit])),"dd-mmm"),"Closed "&TEXT(INDEX(INTCTable[Date],MATCH("Exit",INTCTable[Entry/Exit])),"dd-mmm")) -> Closed 02-Dec

Sheet STRAT3_BAC
B1: BAC PROTECTIVE PUT | E1: https://finance.yahoo.com/quote/BAC
A3: x | B3: Details | H3: LONG STOCK
B4: Contract | H4: Date | I4: BAC | J4: Stock Price | K4: Entry/Exit | L4: Daily +/- | M4: Cum. Total | N4: Current Account | O4: Margin Payment | P4: Curr. after Margin Payments
B5: Underlying | D5: Bank of America Corporation | H5: 45609 | J5: 0
B6: Contract Size in Stock | D6: 100 | H6: 45610 | J6: 45.9 | K6: Entry | L6: =NVDATable131820222426283032[[#This Row],[Stock Price]]-J5 -> 45.9 | O6: =NVDATable131820222426283032[[#This Row],[Stock Price]]*D6*D15 -> 9180000 | P6: =NVDATable131820222426283032[[#This Row],[Margin Payment]]+NVDATable131820222426283032[[#This Row],[Current Account]] -> 9180000
B7: Strategy | D7: Protecitve Put | H7: 45623 | J7: 47.77 | K7: Exit | L7: =NVDATable131820222426283032[[#This Row],[Stock Price]]-J6 -> 1.87 | M7: =(NVDATable131820222426283032[[#This Row],[Stock Price]]-$J$6)*$D$15*$D$6 -> 374000 | N7: =P6+NVDATable131820222426283032[[#This Row],[Cum. Total]]-M6 -> 9554000 | O7: 0 | P7: =NVDATable131820222426283032[[#This Row],[Margin Payment]]+NVDATable131820222426283032[[#This Row],[Current Account]] -> 9554000
B8: Strategy Type | D8: Hedge
H9: LONG PUT
D10: LONG STOCK | E10: LONG PUT | H10: Date | I10: BAC | J10: Last Price | K10: Entry/Exit | L10: Daily +/- | M10: Cum. Total | N10: Current Account | O10: Margin Payment | P10: Curr. after Margin Payments
B11: Start Date | D11: 45610 | E11: 45610 | H11: 45609 | J11: 0
B12: Expiry Date | D12: N/A | E12: 45674 | H12: 45610 | I12: =J6 -> 45.9 | J12: 1.34 | K12: Entry | L12: =NVDATable13141921232527293133[[#This Row],[Last Price]]-J11 -> 1.34 | O12: =NVDATable13141921232527293133[[#This Row],[Last Price]]*D6*-E16 -> -2680 | P12: =NVDATable13141921232527293133[[#This Row],[Margin Payment]]+NVDATable13141921232527293133[[#This Row],[Current Account]] -> -2680
B13: Contract Symbol | D13: BAC | E13: P3Q1 | H13: 45623 | J13: 0.66 | K13: Exit | L13: =NVDATable13141921232527293133[[#This Row],[Last Price]]-J12 -> -0.68 | M13: =(NVDATable13141921232527293133[[#This Row],[Last Price]]-$J$12)*$E$16*$D$6 -> -1360 | N13: =P12+NVDATable13141921232527293133[[#This Row],[Cum. Total]]-M12 -> -4040 | O13: 0 | P13: =NVDATable13141921232527293133[[#This Row],[Margin Payment]]+NVDATable13141921232527293133[[#This Row],[Current Account]] -> -4040
B14: Position Type | D14: LONG STOCK | E14: LONG PUT
B15: Position (Stock) | D15: 2000 | E15: =D15 -> 2000
B16: Position (Contracts) | D16: 0 | E16: =E15/$D$6 -> 20
B17: Contract Value, USD | D17: =D16*J6*D6 -> 0 | E17: =D6*E16*J12 -> 2680
B18: Strike Price | D18: 0 | E18: 45
B19: P&L at Close | D19: =M7 -> 374000 | E19: =M13 -> -1360
B20: Total | F20: =D19+E19 -> 372640
B22: Cash / Margin | F22: Margin
B23: Cash Invested, USD | D23: =D15*$J$6*D6 -> 9180000 | E23: =-O12 -> 2680 | F23: Collected Premium, USD
B24: Initial Margin, % | D24: - | E24: - | F24: Margin per Share
B25: Total, Maitenance Margin, USD | D25: - | E25: - | F25: Total Margin Required
B26: Margin Call Threshold | D26: - | E26: - | F26: Margin Call Threshold

Sheet STRAT3_WFC
B1: WFC PROTECTIVE PUT | E1: https://finance.yahoo.com/quote/WFC
A3: x | B3: Details | H3: LONG STOCK
B4: Contract | H4: Date | I4: BAC | J4: Stock Price | K4: Entry/Exit | L4: Daily +/- | M4: Cum. Total | N4: Current Account | O4: Margin Payment | P4: Curr. after Margin Payments
B5: Underlying | D5: Wells Fargo & Company | H5: 45609 | J5: 0
B6: Contract Size in Stock | D6: 100 | H6: 45610 | J6: 72.8 | K6: Entry | L6: =NVDATable1318202224262830[[#This Row],[Stock Price]]-J5 -> 72.8 | O6: =NVDATable1318202224262830[[#This Row],[Stock Price]]*D6*D15 -> 8736000 | P6: =NVDATable1318202224262830[[#This Row],[Margin Payment]]+NVDATable1318202224262830[[#This Row],[Current Account]] -> 8736000
B7: Strategy | D7: Protecitve Put | H7: 45623 | J7: 77.21 | K7: Exit | L7: =NVDATable1318202224262830[[#This Row],[Stock Price]]-J6 -> 4.41 | M7: =(NVDATable1318202224262830[[#This Row],[Stock Price]]-$J$6)*$D$15*$D$6 -> 529200 | N7: =P6+NVDATable1318202224262830[[#This Row],[Cum. Total]]-M6 -> 9265200 | O7: 0 | P7: =NVDATable1318202224262830[[#This Row],[Margin Payment]]+NVDATable1318202224262830[[#This Row],[Current Account]] -> 9265200
B8: Strategy Type | D8: Hedge
H9: LONG PUT
D10: LONG STOCK | E10: LONG PUT | H10: Date | I10: BAC | J10: Last Price | K10: Entry/Exit | L10: Daily +/- | M10: Cum. Total | N10: Current Account | O10: Margin Payment | P10: Curr. after Margin Payments
B11: Start Date | D11: 45610 | E11: 45610 | H11: 45609 | J11: 0
B12: Expiry Date | D12: N/A | E12: 45653 | H12: 45610 | I12: =J6 -> 72.8 | J12: 1.94 | K12: Entry | L12: =NVDATable131419212325272931[[#This Row],[Last Price]]-J11 -> 1.94 | O12: =NVDATable131419212325272931[[#This Row],[Last Price]]*D6*-E16 -> -2328 | P12: =NVDATable131419212325272931[[#This Row],[Margin Payment]]+NVDATable131419212325272931[[#This Row],[Current Account]] -> -2328
B13: Contract Symbol | D13: WFC | E13: P6X4 | H13: 45623 | J13: 0.52 | K13: Exit | L13: =NVDATable131419212325272931[[#This Row],[Last Price]]-J12 -> -1.42 | M13: =(NVDATable131419212325272931[[#This Row],[Last Price]]-$J$12)*$E$16*$D$6 -> -1704 | N13: =P12+NVDATable131419212325272931[[#This Row],[Cum. Total]]-M12 -> -4032 | O13: 0 | P13: =NVDATable131419212325272931[[#This Row],[Margin Payment]]+NVDATable131419212325272931[[#This Row],[Current Account]] -> -4032
B14: Position Type | D14: LONG STOCK | E14: LONG PUT
B15: Position (Stock) | D15: 1200 | E15: =D15 -> 1200
B16: Position (Contracts) | D16: 0 | E16: =E15/$D$6 -> 12
B17: Contract Value, USD | D17: =D16*J6*D6 -> 0 | E17: =D6*E16*J12 -> 2328
B18: Strike Price | D18: 0 | E18: 72
B19: P&L at Close | D19: =M7 -> 529200 | E19: =M13 -> -1704
B20: Total | F20: =D19+E19 -> 527496
B22: Cash / Margin | F22: Margin
B23: Cash Invested, USD | D23: =D15*$J$6*D6 -> 8736000 | E23: =-O12 -> 2328 | F23: Collected Premium, USD
B24: Initial Margin, % | D24: - | E24: - | F24: Margin per Share
B25: Total, Maitenance Margin, USD | D25: - | E25: - | F25: Total Margin Required
B26: Margin Call Threshold | D26: - | E26: - | F26: Margin Call Threshold

Sheet STRAT3_JPM
B1: JPM PROTECTIVE PUT | E1: https://finance.yahoo.com/quote/JPM
A3: x | B3: Details | H3: LONG STOCK
B4: Contract | H4: Date | I4: JPM | J4: Stock Price | K4: Entry/Exit | L4: Daily +/- | M4: Cum. Total | N4: Current Account | O4: Margin Payment | P4: Curr. after Margin Payments
B5: Underlying | D5: JPMorgan Chase & Co. | H5: 45609 | J5: 0
B6: Contract Size in Stock | D6: 100 | H6: 45610 | J6: 241.87 | K6: Entry | L6: =NVDATable13182022242628[[#This Row],[Stock Price]]-J5 -> 241.87 | O6: =NVDATable13182022242628[[#This Row],[Stock Price]]*D6*D15 -> 12093500 | P6: =NVDATable13182022242628[[#This Row],[Margin Payment]]+NVDATable13182022242628[[#This Row],[Current Account]] -> 12093500
B7: Strategy | D7: Protecitve Put | H7: 45623 | J7: 249.79 | K7: Exit | L7: =NVDATable13182022242628[[#This Row],[Stock Price]]-J6 -> 7.92 | M7: =(NVDATable13182022242628[[#This Row],[Stock Price]]-$J$6)*$D$15*$D$6 -> 396000 | N7: =P6+NVDATable13182022242628[[#This Row],[Cum. Total]]-M6 -> 12489500 | O7: 0 | P7: =NVDATable13182022242628[[#This Row],[Margin Payment]]+NVDATable13182022242628[[#This Row],[Current Account]] -> 12489500
B8: Strategy Type | D8: Hedge
H9: LONG PUT
D10: LONG STOCK | E10: LONG PUT | H10: Date | I10: JPM | J10: Last Price | K10: Entry/Exit | L10: Daily +/- | M10: Cum. Total | N10: Current Account | O10: Margin Payment | P10: Curr. after Margin Payments
B11: Start Date | D11: 45610 | E11: 45610 | H11: 45609 | J11: 0
B12: Expiry Date | D12: N/A | E12: 45632 | H12: 45610 | I12: =J6 -> 241.87 | J12: 3.18 | K12: Entry | L12: =NVDATable1314192123252729[[#This Row],[Last Price]]-J11 -> 3.18 | O12: =NVDATable1314192123252729[[#This Row],[Last Price]]*D6*-E16 -> -1590 | P12: =NVDATable1314192123252729[[#This Row],[Margin Payment]]+NVDATable1314192123252729[[#This Row],[Current Account]] -> -1590
B13: Contract Symbol | D13: JPM | E13: P0RG | H13: 45623 | J13: 0.29 | K13: Exit | L13: =NVDATable1314192123252729[[#This Row],[Last Price]]-J12 -> -2.89 | M13: =(NVDATable1314192123252729[[#This Row],[Last Price]]-$J$12)*$E$16*$D$6 -> -1445 | N13: =P12+NVDATable1314192123252729[[#This Row],[Cum. Total]]-M12 -> -3035 | O13: 0 | P13: =NVDATable1314192123252729[[#This Row],[Margin Payment]]+NVDATable1314192123252729[[#This Row],[Current Account]] -> -3035
B14: Position Type | D14: LONG STOCK | E14: LONG PUT
B15: Position (Stock) | D15: 500 | E15: 500
B16: Position (Contracts) | D16: 0 | E16: =E15/$D$6 -> 5
B17: Contract Value, USD | D17: =D16*J6*D6 -> 0 | E17: =D6*E16*J12 -> 1590
B18: Strike Price | D18: 0 | E18: 240
B19: P&L at Close | D19: =M7 -> 396000 | E19: =M13 -> -1445
B20: Total | F20: =D19+E19 -> 394555
B22: Cash / Margin | F22: Margin
B23: Cash Invested, USD | D23: =D15*$J$6*D6 -> 12093500 | E23: =-O12 -> 1590 | F23: Collected Premium, USD
B24: Initial Margin, % | D24: - | E24: - | F24: Margin per Share
B25: Total, Maitenance Margin, USD | D25: - | E25: - | F25: Total Margin Required
B26: Margin Call Threshold | D26: - | E26: - | F26: Margin Call Threshold

Sheet STRAT2_OXY
B1: OXY BEAR SPREAD (PUT) | E1: https://finance.yahoo.com/quote/OXY
A3: x | B3: Details | H3: LONG PUT
B4: Contract | H4: Date | I4: OXY | J4: Last Price | K4: Entry/Exit | L4: Daily +/- | M4: Cum. Total | N4: Current Account | O4: Margin Payment | P4: Curr. after Margin Payments
B5: Underlying | D5: Occidental Petroleum Corporation | H5: 45601 | J5: 0
B6: Contract Size in Stock | D6: 100 | H6: 45602 | J6: 1.98 | K6: Entry | L6: =NVDATable131820222426[[#This Row],[Last Price]]-J5 -> 1.98 | O6: =NVDATable131820222426[[#This Row],[Last Price]]*D6*D16 -> 990000 | P6: =NVDATable131820222426[[#This Row],[Margin Payment]]+NVDATable131820222426[[#This Row],[Current Account]] -> 990000
B7: Strategy | D7: Bear Spread | H7: 45623 | J7: 1.76 | K7: Exit | L7: =NVDATable131820222426[[#This Row],[Last Price]]-J6 -> -0.22 | M7: =(NVDATable131820222426[[#This Row],[Last Price]]-$J$6)*$D$16*$D$6 -> -110000 | N7: =P6+NVDATable131820222426[[#This Row],[Cum. Total]]-M6 -> 880000 | O7: 0 | P7: =NVDATable131820222426[[#This Row],[Margin Payment]]+NVDATable131820222426[[#This Row],[Current Account]] -> 880000
B8: Strategy Type | D8: Debit Spread
H9: SHORT PUT
D10: LONG PUT | E10: SHORT PUT | H10: Date | I10: OXY | J10: Last Price | K10: Entry/Exit | L10: Daily +/- | M10: Cum. Total | N10: Current Account | O10: Margin Payment | P10: Curr. after Margin Payments
B11: Start Date | D11: 45602 | E11: 45602 | H11: 45601 | J11: 0
B12: Expiry Date | D12: 45632 | E12: 45632 | H12: 45602 | I12: 51.39 | J12: 1.07 | K12: Entry | L12: =NVDATable13141921232527[[#This Row],[Last Price]]-J11 -> 1.07 | O12: =NVDATable13141921232527[[#This Row],[Last Price]]*D6*-E16 -> -535000 | P12: =NVDATable13141921232527[[#This Row],[Margin Payment]]+NVDATable13141921232527[[#This Row],[Current Account]] -> -535000
B13: Contract Symbol | D13: PTV9 | E13: PW8 | H13: 45623 | J13: 0.51 | K13: Exit | L13: =NVDATable13141921232527[[#This Row],[Last Price]]-J12 -> -0.56 | M13: =(NVDATable13141921232527[[#This Row],[Last Price]]-$J$12)*$E$16*$D$6 -> -280000 | N13: =P12+NVDATable13141921232527[[#This Row],[Cum. Total]]-M12 -> -815000 | O13: 0 | P13: =NVDATable13141921232527[[#This Row],[Margin Payment]]+NVDATable13141921232527[[#This Row],[Current Account]] -> -815000
B14: Position Type | D14: LONG PUT | E14: SHOT PUT
B15: Position (Stock) | D15: 500000 | E15: 500000
B16: Position (Contracts) | D16: =D15/$D$6 -> 5000 | E16: =E15/$D$6 -> 5000
B17: Contract Value, USD | D17: =D16*J6*D6 -> 990000 | E17: =D6*E16*J12 -> 535000
B18: Strike Price | D18: 52 | E18: 50
B19: P&L at Close | D19: =M7 -> -110000 | E19: =-M13 -> 280000
B20: Total | F20: =D19+E19 -> 170000
B22: Cash / Margin | F22: Margin
B23: Cash Invested, USD | D23: =D16*$J$6*D6 -> 990000 | E23: =-E16*$J$12*D6 -> -535000 | F23: Collected Premium, USD
B24: Initial Margin, % | D24: - | E24: =J12+0.2*I12- (I12-E18) -> 9.958 | F24: Margin per Share
B25: Total, Maitenance Margin, USD | D25: - | E25: =E24*E15 -> 4979000 | F25: Total Margin Required
B26: Margin Call Threshold | D26: - | E26: - | F26: Margin Call Threshold

Sheet STRAT2_CVX
B1: XOM BEAR SPREAD (PUT) | E1: https://finance.yahoo.com/quote/CVX
A3: x | B3: Details | H3: LONG PUT
B4: Contract | H4: Date | I4: CVX | J4: Last Price | K4: Entry/Exit | L4: Daily +/- | M4: Cum. Total | N4: Current Account | O4: Margin Payment | P4: Curr. after Margin Payments
B5: Underlying | D5: Chevron Corporation | H5: 45601 | J5: 0
B6: Contract Size in Stock | D6: 100 | H6: 45602 | J6: 5.85 | K6: Entry | L6: =NVDATable1318202224[[#This Row],[Last Price]]-J5 -> 5.85 | O6: =NVDATable1318202224[[#This Row],[Last Price]]*D6*D16 -> 1462500 | P6: =NVDATable1318202224[[#This Row],[Margin Payment]]+NVDATable1318202224[[#This Row],[Current Account]] -> 1462500
B7: Strategy | D7: Bear Spread | H7: 45608 | J7: 6.96 | K7: Exit | L7: =NVDATable1318202224[[#This Row],[Last Price]]-J6 -> 1.11 | M7: =(NVDATable1318202224[[#This Row],[Last Price]]-$J$6)*$D$16*$D$6 -> 277500 | N7: =P6+NVDATable1318202224[[#This Row],[Cum. Total]]-M6 -> 1740000 | O7: 0 | P7: =NVDATable1318202224[[#This Row],[Margin Payment]]+NVDATable1318202224[[#This Row],[Current Account]] -> 1740000
B8: Strategy Type | D8: Debit Spread
H9: SHORT PUT
D10: LONG PUT | E10: SHORT PUT | H10: Date | I10: CVX | J10: Last Price | K10: Entry/Exit | L10: Daily +/- | M10: Cum. Total | N10: Current Account | O10: Margin Payment | P10: Curr. after Margin Payments
B11: Start Date | D11: 45602 | E11: 45602 | H11: 45601 | J11: 0
B12: Expiry Date | D12: 45646 | E12: 45646 | H12: 45602 | I12: 157.72 | J12: 3.23 | K12: Entry | L12: =NVDATable131419212325[[#This Row],[Last Price]]-J11 -> 3.23 | O12: =NVDATable131419212325[[#This Row],[Last Price]]*D6*-E16 -> -807500 | P12: =NVDATable131419212325[[#This Row],[Margin Payment]]+NVDATable131419212325[[#This Row],[Current Account]] -> -807500
B13: Contract Symbol | D13: P9Q | E13: PW1 | H13: 45608 | J13: 3.6 | K13: Exit | L13: =NVDATable131419212325[[#This Row],[Last Price]]-J12 -> 0.37 | M13: =(NVDATable131419212325[[#This Row],[Last Price]]-$J$12)*$E$16*$D$6 -> 92500 | N13: =P12+NVDATable131419212325[[#This Row],[Cum. Total]]-M12 -> -715000 | O13: 0 | P13: =NVDATable131419212325[[#This Row],[Margin Payment]]+NVDATable131419212325[[#This Row],[Current Account]] -> -715000
B14: Position Type | D14: LONG PUT | E14: SHORT PUT
B15: Position (Stock) | D15: 250000 | E15: 250000
B16: Position (Contracts) | D16: =D15/$D$6 -> 2500 | E16: =E15/$D$6 -> 2500
B17: Contract Value, USD | D17: =D16*J6*D6 -> 1462500 | E17: =D6*E16*J12 -> 807500
B18: Strike Price | D18: 160 | E18: 155
B19: P&L at Close | D19: =M7 -> 277500 | E19: =-M13 -> -92500
B20: Total | F20: =D19+E19 -> 185000
B22: Cash / Margin | F22: Margin
B23: Cash Invested, USD | D23: =D16*$J$6*D6 -> 1462500 | E23: =-E16*$J$12*D6 -> -807500 | F23: Collected Premium, USD
B24: Initial Margin, % | D24: - | E24: =J12+0.2*I12- (I12-E18) -> 32.054 | F24: Margin per Share
B25: Total, Maitenance Margin, USD | D25: - | E25: =E24*E15 -> 8013500 | F25: Total Margin Required
B26: Margin Call Threshold | D26: - | E26: - | F26: Margin Call Threshold

Sheet STRAT2_XOM
B1: XOM BEAR SPREAD (PUT) | E1: https://finance.yahoo.com/quote/XOM/
A3: x | B3: Details | H3: LONG PUT
B4: Contract | H4: Date | I4: XOM | J4: Last Price | K4: Entry/Exit | L4: Daily +/- | M4: Cum. Total | N4: Current Account | O4: Margin Payment | P4: Curr. after Margin Payments
B5: Underlying | D5: Exxon Mobil Corporation | H5: 45601 | J5: 0
B6: Contract Size in Stock | D6: 100 | H6: 45602 | J6: 4.15 | K6: Entry | L6: =NVDATable13182022[[#This Row],[Last Price]]-J5 -> 4.15 | O6: =NVDATable13182022[[#This Row],[Last Price]]*D6*D16 -> 830000 | P6: =NVDATable13182022[[#This Row],[Margin Payment]]+NVDATable13182022[[#This Row],[Current Account]] -> 830000
B7: Strategy | D7: Bear Spread | H7: 45623 | J7: 3.6 | K7: Exit | L7: =NVDATable13182022[[#This Row],[Last Price]]-J6 -> -0.55 | M7: =(NVDATable13182022[[#This Row],[Last Price]]-$J$6)*$D$16*$D$6 -> -110000 | N7: =P6+NVDATable13182022[[#This Row],[Cum. Total]]-M6 -> 720000 | O7: 0 | P7: =NVDATable13182022[[#This Row],[Margin Payment]]+NVDATable13182022[[#This Row],[Current Account]] -> 720000
B8: Strategy Type | D8: Debit Spread
H9: SHORT PUT
D10: LONG PUT | E10: SHORT PUT | H10: Date | I10: XOM | J10: Last Price | K10: Entry/Exit | L10: Daily +/- | M10: Cum. Total | N10: Current Account | O10: Margin Payment | P10: Curr. after Margin Payments
B11: Start Date | D11: 45602 | E11: 45602 | H11: 45601 | J11: 0
B12: Expiry Date | D12: 45639 | E12: 45639 | H12: 45602 | I12: 121 | J12: 1.62 | K12: Entry | L12: =NVDATable1314192123[[#This Row],[Last Price]]-J11 -> 1.62 | O12: =NVDATable1314192123[[#This Row],[Last Price]]*D6*-E16 -> -324000 | P12: =NVDATable1314192123[[#This Row],[Margin Payment]]+NVDATable1314192123[[#This Row],[Current Account]] -> -324000
B13: Contract Symbol | D13: PP3Q | E13: P29F | H13: 45623 | J13: 1.6 | K13: Exit | L13: =NVDATable1314192123[[#This Row],[Last Price]]-J12 -> -0.02 | M13: =(NVDATable1314192123[[#This Row],[Last Price]]-$J$12)*$E$16*$D$6 -> -4000 | N13: =P12+NVDATable1314192123[[#This Row],[Cum. Total]]-M12 -> -328000 | O13: 0 | P13: =NVDATable1314192123[[#This Row],[Margin Payment]]+NVDATable1314192123[[#This Row],[Current Account]] -> -328000
B14: Position Type | D14: LONG PUT | E14: SHOT PUT
B15: Position (Stock) | D15: 200000 | E15: 200000
B16: Position (Contracts) | D16: =D15/$D$6 -> 2000 | E16: =E15/$D$6 -> 2000
B17: Contract Value, USD | D17: =D16*J6*D6 -> 830000 | E17: =D6*E16*J12 -> 324000
B18: Strike Price | D18: 122 | E18: 117
B19: P&L at Close | D19: =M7 -> -110000 | E19: =-M13 -> 4000
B20: Total | F20: =D19+E19 -> -106000
B22: Cash / Margin | F22: Margin
B23: Cash Invested, USD | D23: =D16*$J$6*D6 -> 830000 | E23: =-E16*$J$12*D6 -> -324000 | F23: Collected Premium, USD
B24: Initial Margin, % | D24: - | E24: =J12+0.2*I12- (I12-E18) -> 21.82 | F24: Margin per Share
B25: Total, Maitenance Margin, USD | D25: - | E25: =E24*E15 -> 4364000 | F25: Total Margin Required
B26: Margin Call Threshold | D26: - | E26: - | F26: Margin Call Threshold

Sheet STRAT1_YUM
B1: YUM CALENDAR SPREAD | E1: https://finance.yahoo.com/quote/YUM/
A3: x | B3: Details | H3: LONG CALL
B4: Contract | H4: Date | I4: YUM | J4: Last Price | K4: Entry/Exit | L4: Daily +/- | M4: Cum. Total | N4: Current Account | O4: Margin Payment | P4: Curr. after Margin Payments
B5: Underlying | D5: Yum! Brands, Inc. | H5: 45597 | J5: 0
B6: Contract Size in Stock | D6: 100 | H6: 45600 | J6: 4.1 | K6: Entry | L6: =NVDATable131820[[#This Row],[Last Price]]-J5 -> 4.1 | O6: =NVDATable131820[[#This Row],[Last Price]]*D6*D16 -> 328000 | P6: =NVDATable131820[[#This Row],[Margin Payment]]+NVDATable131820[[#This Row],[Current Account]] -> 328000
B7: Strategy | D7: Calendar Spread | H7: 45608 | J7: 4 | K7: Exit | L7: =NVDATable131820[[#This Row],[Last Price]]-J6 -> -0.1 | M7: =(NVDATable131820[[#This Row],[Last Price]]-$J$6)*$D$16*$D$6 -> -8000 | N7: =P6+NVDATable131820[[#This Row],[Cum. Total]]-M6 -> 320000 | O7: 0 | P7: =NVDATable131820[[#This Row],[Margin Payment]]+NVDATable131820[[#This Row],[Current Account]] -> 320000
B8: Strategy Type | D8: Debit Spread
H9: SHORT CALL
D10: LONG CALL | E10: SHORT CALL | H10: Date | I10: YUM | J10: Last Price | K10: Entry/Exit | L10: Daily +/- | M10: Cum. Total | N10: Current Account | O10: Margin Payment | P10: Curr. after Margin Payments
B11: Start Date | D11: 45600 | E11: 45600 | H11: 45597 | J11: 0
B12: Expiry Date | D12: 45674 | E12: 45611 | H12: 45600 | I12: 34.34 | J12: 2.29 | K12: Entry | L12: =NVDATable13141921[[#This Row],[Last Price]]-J11 -> 2.29 | O12: =NVDATable13141921[[#This Row],[Last Price]]*D6*-E16 -> -183200 | P12: =NVDATable13141921[[#This Row],[Margin Payment]]+NVDATable13141921[[#This Row],[Current Account]] -> -183200
B13: Contract Symbol | D13: CVW | E13: CLCC | H13: 45608 | J13: 0.65 | K13: Exit | L13: =NVDATable13141921[[#This Row],[Last Price]]-J12 -> -1.64 | M13: =(NVDATable13141921[[#This Row],[Last Price]]-$J$12)*$E$16*$D$6 -> -131200 | N13: =P12+NVDATable13141921[[#This Row],[Cum. Total]]-M12 -> -314400 | O13: 0 | P13: =NVDATable13141921[[#This Row],[Margin Payment]]+NVDATable13141921[[#This Row],[Current Account]] -> -314400
B14: Position Type | D14: LONG CALL | E14: SHORT CALL
B15: Position (Stock) | D15: 80000 | E15: 80000
B16: Position (Contracts) | D16: =D15/$D$6 -> 800 | E16: =E15/$D$6 -> 800
B17: Contract Value, USD | D17: =D16*J6*D6 -> 328000 | E17: =D6*E16*J12 -> 183200
B18: Strike Price | D18: 135 | E18: 135
B19: P&L at Close | D19: =M7 -> -8000 | E19: =-M13 -> 131200
B20: Total | F20: =D19+E19 -> 123200
B22: Cash / Margin | F22: Margin
B23: Cash Invested, USD | D23: =D16*$J$6*D6 -> 328000 | E23: =-E16*$J$12*D6 -> -183200 | F23: Collected Premium, USD
B24: Initial Margin, % | D24: - | E24: =J12+0.2*I12- (I12-E18) -> 109.818 | F24: Margin per Share
B25: Total, Maitenance Margin, USD | D25: - | E25: =E24*E15 -> 8785440 | F25: Total Margin Required
B26: Margin Call Threshold | D26: - | E26: - | F26: Margin Call Threshold

Sheet STRAT1_DJT
B1: DJT CALENDAR SPREAD | E1: https://finance.yahoo.com/quote/DJT/
A3: x | B3: Details | H3: LONG CALL
B4: Contract | H4: Date | I4: DJT | J4: Last Price | K4: Entry/Exit | L4: Daily +/- | M4: Cum. Total | N4: Current Account | O4: Margin Payment | P4: Curr. after Margin Payments
B5: Underlying | D5: Trump Media & Technology Group Corp. | H5: 45597 | J5: 0
B6: Contract Size in Stock | D6: 100 | H6: 45600 | J6: 14.1 | K6: Entry | L6: =NVDATable1318[[#This Row],[Last Price]]-J5 -> 14.1 | O6: =NVDATable1318[[#This Row],[Last Price]]*D6*D16 -> 11280000 | P6: =NVDATable1318[[#This Row],[Margin Payment]]+NVDATable1318[[#This Row],[Current Account]] -> 11280000
B7: Strategy | D7: Calendar Spread | H7: 45614 | J7: 8.6 | K7: Exit | L7: =NVDATable1318[[#This Row],[Last Price]]-J6 -> -5.5 | M7: =(NVDATable1318[[#This Row],[Last Price]]-$J$6)*$D$16*$D$6 -> -4400000 | N7: =P6+NVDATable1318[[#This Row],[Cum. Total]]-M6 -> 6880000 | O7: 0 | P7: =NVDATable1318[[#This Row],[Margin Payment]]+NVDATable1318[[#This Row],[Current Account]] -> 6880000
B8: Strategy Type | D8: Debit Spread
H9: SHORT CALL
D10: LONG CALL | E10: SHORT CALL | H10: Date | I10: DJT | J10: Last Price | K10: Entry/Exit | L10: Daily +/- | M10: Cum. Total | N10: Current Account | O10: Margin Payment | P10: Curr. after Margin Payments
B11: Start Date | D11: 45600 | E11: 45600 | H11: 45597 | J11: 0
B12: Expiry Date | D12: 45674 | E12: 45625 | H12: 45600 | I12: 34.34 | J12: 11.77 | K12: Entry | L12: =NVDATable131419[[#This Row],[Last Price]]-J11 -> 11.77 | O12: =NVDATable131419[[#This Row],[Last Price]]*D6*-E16 -> -9416000 | P12: =NVDATable131419[[#This Row],[Margin Payment]]+NVDATable131419[[#This Row],[Current Account]] -> -9416000
B13: Contract Symbol | D13: C7KL | E13: C20C | H13: 45614 | J13: 4.8 | K13: Exit | L13: =NVDATable131419[[#This Row],[Last Price]]-J12 -> -6.97 | M13: =(NVDATable131419[[#This Row],[Last Price]]-$J$12)*$E$16*$D$6 -> -5576000 | N13: =P12+NVDATable131419[[#This Row],[Cum. Total]]-M12 -> -14992000 | O13: 0 | P13: =NVDATable131419[[#This Row],[Margin Payment]]+NVDATable131419[[#This Row],[Current Account]] -> -14992000
B14: Position Type | D14: LONG CALL | E14: SHORT CALL
B15: Position (Stock) | D15: 800000 | E15: 800000
B16: Position (Contracts) | D16: =D15/$D$6 -> 8000 | E16: =E15/$D$6 -> 8000
B17: Contract Value, USD | D17: =D16*J6*D6 -> 11280000 | E17: =D6*E16*J12 -> 9416000
B18: Strike Price | D18: 30 | E18: 30
B19: P&L at Close | D19: =M7 -> -4400000 | E19: =-M13 -> 5576000
B20: Total | F20: =D19+E19 -> 1176000
B22: Cash / Margin | F22: Margin
B23: Cash Invested, USD | D23: =D16*$J$6*D6 -> 11280000 | E23: =-E16*$J$12*D6 -> -9416000 | F23: Collected Premium, USD
B24: Initial Margin, % | D24: - | E24: =J12+0.2*I12- (I12-E18) -> 14.298 | F24: Margin per Share
B25: Total, Maitenance Margin, USD | D25: - | E25: =E24*E15 -> 11438400 | F25: Total Margin Required
B26: Margin Call Threshold | D26: - | E26: - | F26: Margin Call Threshold

Sheet STRAT1_TSLA
B1: TSLA CALENDAR SPREAD | E1: https://finance.yahoo.com/quote/TSLA/
A3: x | B3: Details | H3: LONG CALL
B4: Contract | H4: Date | I4: TSLA | J4: Last Price | K4: Entry/Exit | L4: Daily +/- | M4: Cum. Total | N4: Current Account | O4: Margin Payment | P4: Curr. after Margin Payments
B5: Underlying | D5: Tesla Inc | H5: 45597 | J5: 2.88
B6: Contract Size in Stock | D6: 100 | H6: 45600 | J6: 2.4 | K6: Entry | L6: =NVDATable13[[#This Row],[Last Price]]-J5 -> -0.48 | O6: =NVDATable13[[#This Row],[Last Price]]*D6*D16 -> 192000 | P6: =NVDATable13[[#This Row],[Margin Payment]]+NVDATable13[[#This Row],[Current Account]] -> 192000
B7: Strategy | D7: Calendar Spread | H7: 45614 | J7: 29.8 | K7: Exit | L7: =NVDATable13[[#This Row],[Last Price]]-J6 -> 27.4 | M7: =(NVDATable13[[#This Row],[Last Price]]-$J$6)*$D$16*$D$6 -> 2192000 | N7: =P6+NVDATable13[[#This Row],[Cum. Total]]-M6 -> 2384000 | O7: 0 | P7: =NVDATable13[[#This Row],[Margin Payment]]+NVDATable13[[#This Row],[Current Account]] -> 2384000
B8: Strategy Type | D8: Debit Spread
H9: SHORT CALL
D10: LONG CALL | E10: SHORT CALL | H10: Date | I10: TSLA | J10: Last Price | K10: Entry/Exit | L10: Daily +/- | M10: Cum. Total | N10: Current Account | O10: Margin Payment | P10: Curr. after Margin Payments
B11: Start Date | D11: 45600 | E11: 45600 | H11: 45597 | J11: 0.96
B12: Expiry Date | D12: 45674 | E12: 45639 | H12: 45600 | I12: 242.84 | J12: 0.67 | K12: Entry | L12: =NVDATable1314[[#This Row],[Last Price]]-J11 -> -0.29 | O12: =NVDATable1314[[#This Row],[Last Price]]*D6*-E16 -> -53600 | P12: =NVDATable1314[[#This Row],[Margin Payment]]+NVDATable1314[[#This Row],[Current Account]] -> -53600
B13: Contract Symbol | D13: CX64 | E13: CGW | H13: 45614 | J13: 18.5 | K13: Exit | L13: =NVDATable1314[[#This Row],[Last Price]]-J12 -> 17.83 | M13: =(NVDATable1314[[#This Row],[Last Price]]-$J$12)*$E$16*$D$6 -> 1426400 | N13: =P12+NVDATable1314[[#This Row],[Cum. Total]]-M12 -> 1372800 | O13: 0 | P13: =NVDATable1314[[#This Row],[Margin Payment]]+NVDATable1314[[#This Row],[Current Account]] -> 1372800
B14: Position Type | D14: LONG CALL | E14: SHORT CALL
B15: Position (Stock) | D15: 80000 | E15: 80000
B16: Position (Contracts) | D16: =D15/$D$6 -> 800 | E16: =E15/$D$6 -> 800
B17: Contract Value, USD | D17: =D16*J6*D6 -> 192000 | E17: =D6*E16*J12 -> 53600
B18: Strike Price | D18: 350 | E18: 350
B19: P&L at Close | D19: =M7 -> 2192000 | E19: =-M13 -> -1426400
B20: Total | F20: =D19+E19 -> 765600
B22: Cash / Margin | F22: Margin
B23: Cash Invested, USD | D23: =D16*$J$6*D6 -> 192000 | E23: =-E16*$J$12*D6 -> -53600 | F23: Collected Premium, USD
B24: Initial Margin, % | D24: - | E24: =J12+0.2*I12- (I12-E18) -> 156.398 | F24: Margin per Share
B25: Total, Maitenance Margin, USD | D25: - | E25: =E24*E15 -> 12511840 | F25: Total Margin Required
B26: Margin Call Threshold | D26: - | E26: - | F26: Margin Call Threshold

Sheet H1_Lithium
B1: Lithium Futures | D1: =+HYPERLINK("https://www.cmegroup.com/markets/metals/battery-metals/lithium-hydroxide-cif-cjk-fastmarkets.contractSpecs.html") -> https://www.cmegroup.com/markets/metals/battery-metals/lithium-hydroxide-cif-cjk-fastmarkets.contractSpecs.html
A4: x | B4: Details | G4: Date | H4: Spot Price | I4: Settle $/KG | J4: Daily +/- | K4: Entry/Exit | L4: Daily Per KG | M4: Daily Total | N4: Cum. Per KG | O4: Cum. Total | P4: Current Account | Q4: Margin Payment | R4: Curr. after Margin Payments
B5: Contract | G5: 45574 | H5: 10.22 | I5: 11.48 | P5: 0 | Q5: 0 | R5: =P5+Q5 -> 0
B6: Underlying | D6: Lithium Hydroxide CIF CJK (Fastmarkets) | G6: 45575 | H6: 10.1 | I6: 11.26 | J6: =I6-I5 -> -0.22 | K6: Entry | L6: =J6 -> -0.22 | P6: 0 | Q6: =D18 -> 5984000 | R6: =P6+Q6 -> 5984000
B7: Contract Size in KG | D7: 1000 | G7: 45576 | H7: 9.95 | I7: 11.29 | J7: =I7-I6 -> 0.03 | L7: =J7 -> 0.03 | M7: =$D$12*L7 -> 84489.796 | N7: =I7-$I$6 -> 0.03 | O7: =N7*$D$12 -> 84489.796 | P7: =R6+M7 -> 6068489.8 | Q7: =IF(P7<$D$22, $D$18-P7, 0) -> 0 | R7: =P7+Q7 -> 6068489.8
B8: Start Date | D8: 45566 | G8: 45579 | H8: 9.56 | I8: 11.25 | J8: =I8-I7 -> -0.04 | L8: =J8 -> -0.04 | M8: =$D$12*L8 -> -112653.06 | N8: =I8-$I$6 -> -0.01 | O8: =N8*$D$12 -> -28163.265 | P8: =R7+M8 -> 5955836.7 | Q8: =IF(P8<$D$22, $D$18-P8, 0) -> 0 | R8: =P8+Q8 -> 5955836.7
B9: Delivery Date | D9: 45689 | G9: 45580 | H9: 10.1 | I9: 11.24 | J9: =I9-I8 -> -0.01 | L9: =J9 -> -0.01 | M9: =$D$12*L9 -> -28163.265 | N9: =I9-$I$6 -> -0.02 | O9: =N9*$D$12 -> -56326.531 | P9: =R8+M9 -> 5927673.5 | Q9: =IF(P9<$D$22, $D$18-P9, 0) -> 0 | R9: =P9+Q9 -> 5927673.5
B10: Contract Symbol | D10: LTHG2025 | G10: 45581 | H10: 10.87 | I10: 11.11 | J10: =I10-I9 -> -0.13 | L10: =J10 -> -0.13 | M10: =$D$12*L10 -> -366122.45 | N10: =I10-$I$6 -> -0.15 | O10: =N10*$D$12 -> -422448.98 | P10: =R9+M10 -> 5561551 | Q10: =IF(P10<$D$22, $D$18-P10, 0) -> 0 | R10: =P10+Q10 -> 5561551
B11: Position Type | D11: LONG | G11: 45582 | I11: 10.9 | J11: =I11-I10 -> -0.21 | L11: =J11 -> -0.21 | M11: =$D$12*L11 -> -591428.57 | N11: =I11-$I$6 -> -0.36 | O11: =N11*$D$12 -> -1013877.6 | P11: =R10+M11 -> 4970122.4 | Q11: =IF(P11<$D$22, $D$18-P11, 0) -> 0 | R11: =P11+Q11 -> 4970122.4
B12: Position (KG) | D12: 2816326.5 | G12: 45584 | I12: 11 | J12: =I12-I11 -> 0.1 | L12: =J12 -> 0.1 | M12: =$D$12*L12 -> 281632.65 | N12: =I12-$I$6 -> -0.26 | O12: =N12*$D$12 -> -732244.9 | P12: =R11+M12 -> 5251755.1 | Q12: =IF(P12<$D$22, $D$18-P12, 0) -> 0 | R12: =P12+Q12 -> 5251755.1
B13: Position (Contracts) | D13: =ROUND(D12/D7,0) -> 2816 | G13: 45586 | I13: 10.89 | J13: =I13-I12 -> -0.11 | L13: =J13 -> -0.11 | M13: =$D$12*L13 -> -309795.92 | N13: =I13-$I$6 -> -0.37 | O13: =N13*$D$12 -> -1042040.8 | P13: =R12+M13 -> 4941959.2 | Q13: =IF(P13<$D$22, $D$18-P13, 0) -> 0 | R13: =P13+Q13 -> 4941959.2
B14: Contract Value, USD | D14: =D13*I6*D7 -> 31708160 | G14: 45587 | I14: 10.85 | J14: =I14-I13 -> -0.04 | L14: =J14 -> -0.04 | M14: =$D$12*L14 -> -112653.06 | N14: =I14-$I$6 -> -0.41 | O14: =N14*$D$12 -> -1154693.9 | P14: =R13+M14 -> 4829306.1 | Q14: =IF(P14<$D$22, $D$18-P14, 0) -> 0 | R14: =P14+Q14 -> 4829306.1
G15: 45588 | I15: 10.84 | J15: =I15-I14 -> -0.01 | L15: =J15 -> -0.01 | M15: =$D$12*L15 -> -28163.265 | N15: =I15-$I$6 -> -0.42 | O15: =N15*$D$12 -> -1182857.1 | P15: =R14+M15 -> 4801142.9 | Q15: =IF(P15<$D$22, $D$18-P15, 0) -> 0 | R15: =P15+Q15 -> 4801142.9
B16: Margin | G16: 45589 | I16: 10.8 | J16: =I16-I15 -> -0.04 | L16: =J16 -> -0.04 | M16: =$D$12*L16 -> -112653.06 | N16: =I16-$I$6 -> -0.46 | O16: =N16*$D$12 -> -1295510.2 | P16: =R15+M16 -> 4688489.8 | Q16: =IF(P16<$D$22, $D$18-P16, 0) -> 1295510.2 | R16: =P16+Q16 -> 5984000
B17: Maintenance Margin (Contract) | D17: 1700 | G17: 45590 | I17: 10.6 | J17: =I17-I16 -> -0.2 | L17: =J17 -> -0.2 | M17: =$D$12*L17 -> -563265.31 | N17: =I17-$I$6 -> -0.66 | O17: =N17*$D$12 -> -1858775.5 | P17: =R16+M17 -> 5420734.7 | Q17: =IF(P17<$D$22, $D$18-P17, 0) -> 0 | R17: =P17+Q17 -> 5420734.7
B18: Total Initial Margin, USD | D18: =D17*D19*D13 -> 5984000 | G18: 45622 | I18: 10.44 | J18: =I18-I17 -> -0.16 | K18: Exit | L18: =J18 -> -0.16 | M18: =$D$12*L18 -> -450612.24 | N18: =I18-$I$6 -> -0.82 | O18: =N18*$D$12 -> -2309387.8 | P18: =R17+M18 -> 4970122.4 | Q18: =IF(P18<$D$22, $D$18-P18, 0) -> 0 | R18: =P18+Q18 -> 4970122.4
B19: IBKR Margin Req. | D19: 1.25
B20: Initial Margin, % | D20: =D18/D14 -> 0.18872114
B21: Total, Maitenance Margin, USD | D21: =D17*D13 -> 4787200
B22: Margin Call Threshold | D22: =D21 -> 4787200
B23: Margin Calls in Period | D23: =COUNTIF(LithiumTable[Margin Payment], ">0") -1 -> 1
A24: x

Sheet H2_Cattle
B1: Cattle Futures | D1: =+HYPERLINK("https://www.cmegroup.com/markets/agriculture/livestock/live-cattle.quotes.html") -> https://www.cmegroup.com/markets/agriculture/livestock/live-cattle.quotes.html
L2: Daily P/L | N2: Cum. P/L
A3: x | B3: Details | G3: Date | H3: Spot Price | I3: Settle $/KG | J3: Daily +/- | K3: Entry/Exit | L3: Daily Per KG | M3: Daily Total | N3: Cum. Per KG | O3: Cum. Total | P3: Current Account | Q3: Margin Payment | R3: Curr. after Margin Payments
B4: Contract | G4: 45574 | H4: 1.87225 | I4: 1.87325 | P4: 0 | Q4: 0 | R4: =P4+Q4 -> 0
B5: Underlying | D5: Cattle | G5: 45575 | H5: 1.88275 | I5: 1.8825 | J5: =I5-I4 -> 0.00925 | K5: Entry | L5: =J5 -> 0.00925 | P5: 0 | Q5: =D17 -> 7656250 | R5: =P5+Q5 -> 7656250
B6: Contract Size in Pounds | D6: 40000 | G6: 45576 | H6: 1.87575 | I6: 1.874 | J6: =I6-I5 -> -0.0085 | L6: =J6 -> -0.0085 | M6: =$D$11*L6 -> -850000 | N6: =I6-$I$5 -> -0.0085 | O6: =N6*$D$11 -> -850000 | P6: =R5+M6 -> 6806250 | Q6: =IF(P6<$D$21, $D$17-P6, 0) -> 0 | R6: =P6+Q6 -> 6806250
B7: Start Date | D7: 45566 | G7: 45579 | H7: 1.87925 | I7: 1.87825 | J7: =I7-I6 -> 0.00425 | L7: =J7 -> 0.00425 | M7: =$D$11*L7 -> 425000 | N7: =I7-$I$5 -> -0.00425 | O7: =N7*$D$11 -> -425000 | P7: =R6+M7 -> 7231250 | Q7: =IF(P7<$D$21, $D$17-P7, 0) -> 0 | R7: =P7+Q7 -> 7231250
B8: Delivery Date | D8: 45627 | G8: 45580 | H8: 1.86525 | I8: 1.86625 | J8: =I8-I7 -> -0.012 | L8: =J8 -> -0.012 | M8: =$D$11*L8 -> -1200000 | N8: =I8-$I$5 -> -0.01625 | O8: =N8*$D$11 -> -1625000 | P8: =R7+M8 -> 6031250 | Q8: =IF(P8<$D$21, $D$17-P8, 0) -> 1625000 | R8: =P8+Q8 -> 7656250
B9: Contract Symbol | D9: LEZ2024 | G9: 45581 | I9: 1.86625 | J9: =I9-I8 -> 0 | L9: =J9 -> 0 | M9: =$D$11*L9 -> 0 | N9: =I9-$I$5 -> -0.01625 | O9: =N9*$D$11 -> -1625000 | P9: =R8+M9 -> 7656250 | Q9: =IF(P9<$D$21, $D$17-P9, 0) -> 0 | R9: =P9+Q9 -> 7656250
B10: Position Type | D10: LONG | G10: 45582 | I10: 1.86125 | J10: =I10-I9 -> -0.005 | L10: =J10 -> -0.005 | M10: =$D$11*L10 -> -500000 | N10: =I10-$I$5 -> -0.02125 | O10: =N10*$D$11 -> -2125000 | P10: =R9+M10 -> 7156250 | Q10: =IF(P10<$D$21, $D$17-P10, 0) -> 0 | R10: =P10+Q10 -> 7156250
B11: Position (Pounds) | D11: 100000000 | G11: 45583 | I11: 1.871 | J11: =I11-I10 -> 0.00975 | L11: =J11 -> 0.00975 | M11: =$D$11*L11 -> 975000 | N11: =I11-$I$5 -> -0.0115 | O11: =N11*$D$11 -> -1150000 | P11: =R10+M11 -> 8131250 | Q11: =IF(P11<$D$21, $D$17-P11, 0) -> 0 | R11: =P11+Q11 -> 8131250
B12: Position (Contracts) | D12: =ROUND(D11/D6,0) -> 2500 | G12: 45586 | I12: 1.86825 | J12: =I12-I11 -> -0.00275 | L12: =J12 -> -0.00275 | M12: =$D$11*L12 -> -275000 | N12: =I12-$I$5 -> -0.01425 | O12: =N12*$D$11 -> -1425000 | P12: =R11+M12 -> 7856250 | Q12: =IF(P12<$D$21, $D$17-P12, 0) -> 0 | R12: =P12+Q12 -> 7856250
B13: Contract Value, USD | D13: =D12*I5*D6 -> 188250000 | G13: 45587 | I13: 1.88075 | J13: =I13-I12 -> 0.0125 | L13: =J13 -> 0.0125 | M13: =$D$11*L13 -> 1250000 | N13: =I13-$I$5 -> -0.00175 | O13: =N13*$D$11 -> -175000 | P13: =R12+M13 -> 9106250 | Q13: =IF(P13<$D$21, $D$17-P13, 0) -> 0 | R13: =P13+Q13 -> 9106250
G14: 45588 | I14: 1.8795 | J14: =I14-I13 -> -0.00125 | L14: =J14 -> -0.00125 | M14: =$D$11*L14 -> -125000 | N14: =I14-$I$5 -> -0.003 | O14: =N14*$D$11 -> -300000 | P14: =R13+M14 -> 8981250 | Q14: =IF(P14<$D$21, $D$17-P14, 0) -> 0 | R14: =P14+Q14 -> 8981250
B15: Margin | G15: 45589 | I15: 1.89275 | J15: =I15-I14 -> 0.01325 | L15: =J15 -> 0.01325 | M15: =$D$11*L15 -> 1325000 | N15: =I15-$I$5 -> 0.01025 | O15: =N15*$D$11 -> 1025000 | P15: =R14+M15 -> 10306250 | Q15: =IF(P15<$D$21, $D$17-P15, 0) -> 0 | R15: =P15+Q15 -> 10306250
B16: Maintenance Margin (Contract) | D16: 2450 | G16: 45590 | I16: 1.88975 | J16: =I16-I15 -> -0.003 | L16: =J16 -> -0.003 | M16: =$D$11*L16 -> -300000 | N16: =I16-$I$5 -> 0.00725 | O16: =N16*$D$11 -> 725000 | P16: =R15+M16 -> 10006250 | Q16: =IF(P16<$D$21, $D$17-P16, 0) -> 0 | R16: =P16+Q16 -> 10006250
B17: Total Initial Margin, USD | D17: =D16*D18*D12 -> 7656250 | G17: 45594 | I17: 1.9 | J17: =I17-I16 -> 0.01025 | K17: Exit | L17: =J17 -> 0.01025 | M17: =$D$11*L17 -> 1025000 | N17: =I17-$I$5 -> 0.0175 | O17: =N17*$D$11 -> 1750000 | P17: =R16+M17 -> 11031250 | Q17: =IF(P17<$D$21, $D$17-P17, 0) -> 0 | R17: =P17+Q17 -> 11031250
B18: IBKR Margin Req. | D18: 1.25
B19: Initial Margin, % | D19: =D17/D13 -> 0.040670651
B20: Total, Maitenance Margin, USD | D20: =D16*D12 -> 6125000
B21: Margin Call Threshold | D21: =D20 -> 6125000
B22: Margin Calls in Period | D22: =COUNTIF(CattleTable[Margin Payment], ">0") -1 -> 1

Sheet H3_Soy
B1: Soybean Futures | D1: https://www.cmegroup.com/markets/agriculture/oilseeds/soybean.html
L2: Daily P/L | N2: Cum. P/L
A3: x | B3: Details | G3: Date | H3: Spot Price | I3: Settle $/Bushel | J3: Daily +/- | K3: Entry/Exit | L3: Daily Per Bushel | M3: Daily Total | N3: Cum. Per Bushel | O3: Cum. Total | P3: Current Account | Q3: Margin Payment | R3: Curr. after Margin Payments
B4: Contract | G4: 45583 | P4: 0 | Q4: 0 | R4: =P4+Q4 -> 0
B5: Underlying | D5: Soybean | G5: 45586 | I5: 10.0125 | J5: =I5-I4 -> 10.0125 | K5: Entry | L5: =J5 -> 10.0125 | P5: 0 | Q5: =D17 -> 9900000 | R5: =P5+Q5 -> 9900000
B6: Contract Size in Bushels | D6: 5000 | G6: 45587 | I6: 10.1325 | J6: =I6-I5 -> 0.12 | L6: =J6 -> 0.12 | M6: =$D$11*L6 -> 2640000 | N6: =I6-$I$5 -> 0.12 | O6: =N6*$D$11 -> 2640000 | P6: =R5+M6 -> 12540000 | Q6: =IF(P6<$D$21, $D$17-P6, 0) -> 0 | R6: =P6+Q6 -> 12540000
B7: Start Date | D7: 45566 | G7: 45588 | I7: 10.16 | J7: =I7-I6 -> 0.0275 | L7: =J7 -> 0.0275 | M7: =$D$11*L7 -> 605000 | N7: =I7-$I$5 -> 0.1475 | O7: =N7*$D$11 -> 3245000 | P7: =R6+M7 -> 13145000 | Q7: =IF(P7<$D$21, $D$17-P7, 0) -> 0 | R7: =P7+Q7 -> 13145000
B8: Delivery Date | D8: 45717 | G8: 45589 | I8: 10.1675 | J8: =I8-I7 -> 0.0075 | L8: =J8 -> 0.0075 | M8: =$D$11*L8 -> 165000 | N8: =I8-$I$5 -> 0.155 | O8: =N8*$D$11 -> 3410000 | P8: =R7+M8 -> 13310000 | Q8: =IF(P8<$D$21, $D$17-P8, 0) -> 0 | R8: =P8+Q8 -> 13310000
B9: Contract Symbol | D9: ZSF5 | G9: 45590 | I9: 10.09 | J9: =I9-I8 -> -0.0775 | L9: =J9 -> -0.0775 | M9: =$D$11*L9 -> -1705000 | N9: =I9-$I$5 -> 0.0775 | O9: =N9*$D$11 -> 1705000 | P9: =R8+M9 -> 11605000 | Q9: =IF(P9<$D$21, $D$17-P9, 0) -> 0 | R9: =P9+Q9 -> 11605000
B10: Position Type | D10: LONG | G10: 45603 | I10: 10.375 | J10: =I10-I9 -> 0.285 | K10: Exit | L10: =J10 -> 0.285 | M10: =$D$11*L10 -> 6270000 | N10: =I10-$I$5 -> 0.3625 | O10: =N10*$D$11 -> 7975000 | P10: =R9+M10 -> 17875000 | Q10: =IF(P10<$D$21, $D$17-P10, 0) -> 0 | R10: =P10+Q10 -> 17875000
B11: Position (Bushels) | D11: 22000000
B12: Position (Contracts) | D12: =ROUND(D11/D6,0) -> 4400 | F12: So
B13: Contract Value, USD | D13: =D12*I5*D6 -> 220275000
B15: Margin
B16: Maintenance Margin (Contract) | D16: 1800
B17: Total Initial Margin, USD | D17: =D16*D18*D12 -> 9900000
B18: IBKR Margin Req. | D18: 1.25
B19: Initial Margin, % | D19: =D17/D13 -> 0.04494382
B20: Total, Maitenance Margin, USD | D20: =D16*D12 -> 7920000
B21: Margin Call Threshold | D21: =D20 -> 7920000
B22: Margin Calls in Period | D22: =COUNTIF(SoyTable[Margin Payment], ">0") -1 -> 0

Sheet H4_HO
B1: Heating Oil Futures | D1: https://www.cmegroup.com/markets/energy/refined-products/heating-oil.margins.html
L2: Daily P/L | N2: Cum. P/L
A3: x | B3: Details | G3: Date | H3: Spot Price | I3: Settle $/Gallon | J3: Daily +/- | K3: Entry/Exit | L3: Daily Per Gallon | M3: Daily Total | N3: Cum. Per Gallon | O3: Cum. Total | P3: Current Account | Q3: Margin Payment | R3: Curr. after Margin Payments
B4: Contract | G4: 45583 | P4: 0 | Q4: 0 | R4: =P4+Q4 -> 0
B5: Underlying | D5: NY Harbor ULSD | G5: 45586 | I5: 2.1903 | J5: =I4-I5 -> -2.1903 | K5: Entry | L5: =J5 -> -2.1903 | P5: 0 | Q5: =D17 -> 17278220 | R5: =P5+Q5 -> 17278220
B6: Contract Size in Gallons | D6: 42000 | G6: 45587 | I6: 2.2396 | J6: =I5-I6 -> -0.0493 | L6: =J6 -> -0.0493 | M6: =$D$11*L6 -> -4592064.4 | N6: =$I$5-I6 -> -0.0493 | O6: =N6*$D$11 -> -4592064.4 | P6: =R5+M6 -> 12686156 | Q6: =IF(P6<$D$21, $D$17-P6, 0) -> 4592064.4 | R6: =P6+Q6 -> 17278220
B7: Start Date | D7: 45566 | G7: 45588 | I7: 2.2384 | J7: =I6-I7 -> 0.0012 | L7: =J7 -> 0.0012 | M7: =$D$11*L7 -> 111774.39 | N7: =$I$5-I7 -> -0.0481 | O7: =N7*$D$11 -> -4480290.1 | P7: =R6+M7 -> 17389994 | Q7: =IF(P7<$D$21, $D$17-P7, 0) -> 0 | R7: =P7+Q7 -> 17389994
B8: Delivery Date | D8: 45627 | G8: 45589 | I8: 2.2213 | J8: =I7-I8 -> 0.0171 | L8: =J8 -> 0.0171 | M8: =$D$11*L8 -> 1592785 | N8: =$I$5-I8 -> -0.031 | O8: =N8*$D$11 -> -2887505 | P8: =R7+M8 -> 18982779 | Q8: =IF(P8<$D$21, $D$17-P8, 0) -> 0 | R8: =P8+Q8 -> 18982779
B9: Contract Symbol | D9: HOZ4 | G9: 45590 | I9: 2.2495 | J9: =I8-I9 -> -0.0282 | L9: =J9 -> -0.0282 | M9: =$D$11*L9 -> -2626698.1 | N9: =$I$5-I9 -> -0.0592 | O9: =N9*$D$11 -> -5514203.1 | P9: =R8+M9 -> 16356081 | Q9: =IF(P9<$D$21, $D$17-P9, 0) -> 0 | R9: =P9+Q9 -> 16356081
B10: Position Type | D10: SHORT | G10: 45625 | I10: 2.2032 | J10: =I9-I10 -> 0.0463 | K10: Exit | L10: =J10 -> 0.0463 | M10: =$D$11*L10 -> 4312628.5 | N10: =$I$5-I10 -> -0.0129 | O10: =N10*$D$11 -> -1201574.7 | P10: =R9+M10 -> 20668710 | Q10: =IF(P10<$D$21, $D$17-P10, 0) -> 0 | R10: =P10+Q10 -> 20668710
B11: Position (Gallons) | D11: 93145323
B12: Position (Contracts) | D12: =ROUND(D11/D6,0) -> 2218
B13: Contract Value, USD | D13: =D12*I5*D6 -> 2.0403959e+08
B15: Margin
B16: Maintenance Margin (Contract), short | D16: 6232
B17: Total Initial Margin, USD | D17: =D16*D18*D12 -> 17278220
B18: IBKR Margin Req. | D18: 1.25
B19: Initial Margin, % | D19: =D17/D13 -> 0.084680724
B20: Total, Maitenance Margin, USD | D20: =D16*D12 -> 13822576
B21: Margin Call Threshold | D21: =D20 -> 13822576
B22: Margin Calls in Period | D22: =COUNTIF(HoTable[Margin Payment], ">0") -1 -> 1

Sheet S1_Brent
B1: Brent Futues | D1: =+HYPERLINK("https://www.cmegroup.com/markets/energy/crude-oil/brent-crude-oil.settlements.html#tradeDate=10%2F17%2F2024") -> https://www.cmegroup.com/markets/energy/crude-oil/brent-crude-oil.settlements.html#tradeDate=10%2F17%2F2024
L2: Daily P/L | N2: Cum. P/L
A3: x | B3: Details | G3: Date | H3: Spot Price | I3: Settle $/KG | J3: Daily +/- | K3: Entry/Exit | L3: Daily Per KG | M3: Daily Total | N3: Cum. Per Barrel | O3: Cum. Total | P3: Current Account | Q3: Margin Payment | R3: Curr. after Margin Payments
B4: Contract
B5: Underlying | D5: Brent Crude Oil | G5: 45575 | H5: 78.78 | I5: 79.4 | J5: =I4-BrentTable[[#This Row],[Settle $/KG]] -> -79.4 | K5: Entry | L5: =J5 -> -79.4 | P5: 0 | Q5: =D17 -> 8238000 | R5: =P5+Q5 -> 8238000
B6: Contract Size in Barrels | D6: 1000 | G6: 45576 | H6: 79.06 | I6: 79.04 | J6: =I5-BrentTable[[#This Row],[Settle $/KG]] -> 0.36 | L6: =J6 -> 0.36 | M6: =$D$11*L6 -> 432000 | N6: =$I$5-I6 -> 0.36 | O6: =N6*$D$11 -> 432000 | P6: =R5+M6 -> 8670000 | Q6: =IF(P6<$D$21, $D$17-P6, 0) -> 0 | R6: =P6+Q6 -> 8670000
B7: Start Date | D7: 45566 | G7: 45579 | H7: 77.34 | I7: 77.46 | J7: =I6-BrentTable[[#This Row],[Settle $/KG]] -> 1.58 | L7: =J7 -> 1.58 | M7: =$D$11*L7 -> 1896000 | N7: =$I$5-I7 -> 1.94 | O7: =N7*$D$11 -> 2328000 | P7: =R6+M7 -> 10566000 | Q7: =IF(P7<$D$21, $D$17-P7, 0) -> 0 | R7: =P7+Q7 -> 10566000
B8: Delivery Date | D8: 45627 | G8: 45580 | H8: 74.13 | I8: 74.25 | J8: =I7-BrentTable[[#This Row],[Settle $/KG]] -> 3.21 | L8: =J8 -> 3.21 | M8: =$D$11*L8 -> 3852000 | N8: =$I$5-I8 -> 5.15 | O8: =N8*$D$11 -> 6180000 | P8: =R7+M8 -> 14418000 | Q8: =IF(P8<$D$21, $D$17-P8, 0) -> 0 | R8: =P8+Q8 -> 14418000
B9: Contract Symbol | D9: BZZ4 | G9: 45581 | H9: 74.1 | I9: 74.22 | J9: =I8-BrentTable[[#This Row],[Settle $/KG]] -> 0.03 | K9: Exit | L9: =J9 -> 0.03 | M9: =$D$11*L9 -> 36000 | N9: =$I$5-I9 -> 5.18 | O9: =N9*$D$11 -> 6216000 | P9: =R8+M9 -> 14454000 | Q9: =IF(P9<$D$21, $D$17-P9, 0) -> 0 | R9: =P9+Q9 -> 14454000
B10: Position Type | D10: SHORT
B11: Position (Barrels) | D11: 1200000
B12: Position (Contracts) | D12: =ROUND(D11/D6,0) -> 1200
B13: Contract Value, USD | D13: =D12*I5*D6 -> 95280000
B15: Margin
B16: Maintenance Margin (Contract) | D16: 5492
B17: Total Initial Margin, USD | D17: =D16*D18*D12 -> 8238000
B18: IBKR Margin Req. | D18: 1.25
B19: Initial Margin, % | D19: =D17/D13 -> 0.086460957
B20: Total, Maitenance Margin, USD | D20: =D16*D12 -> 6590400
B21: Margin Call Threshold | D21: =D20 -> 6590400
B22: Margin Calls in Period | D22: =COUNTIF(BrentTable[Margin Payment], ">0") -1 -> 0

Sheet S2_Gold
B1: Gold Futures | D1: =+HYPERLINK("https://www.cmegroup.com/markets/metals/precious/gold.settlements.html") -> https://www.cmegroup.com/markets/metals/precious/gold.settlements.html
A3: x | B3: Details | G3: Date | H3: Spot Price | I3: Settle $/KG | J3: Daily +/- | K3: Entry/Exit | L3: Daily Per KG | M3: Daily Total | N3: Cum. Per KG | O3: Cum. Total | P3: Current Account | Q3: Margin Payment | R3: Curr. after Margin Payments
B4: Contract | G4: 45580 | P4: 0 | Q4: 0 | R4: =P4+Q4 -> 0
B5: Underlying | D5: Gold | G5: 45581 | I5: 2678.6 | J5: =I5-I4 -> 2678.6 | K5: Entry | L5: =J5 -> 2678.6 | P5: 0 | Q5: =D17 -> 13750000 | R5: =P5+Q5 -> 13750000
B6: Contract Size in Troy Oz | D6: 100 | G6: 45582 | I6: 2695.5 | J6: =I6-I5 -> 16.9 | L6: =J6 -> 16.9 | M6: =$D$11*L6 -> 1690000 | N6: =I6-$I$5 -> 16.9 | O6: =N6*$D$11 -> 1690000 | P6: =R5+M6 -> 15440000 | Q6: =IF(P6<$D$21, $D$17-P6, 0) -> 0 | R6: =P6+Q6 -> 15440000
B7: Start Date | D7: 45566 | G7: 45583 | I7: 2725.6 | J7: =I7-I6 -> 30.1 | L7: =J7 -> 30.1 | M7: =$D$11*L7 -> 3010000 | N7: =I7-$I$5 -> 47 | O7: =N7*$D$11 -> 4700000 | P7: =R6+M7 -> 18450000 | Q7: =IF(P7<$D$21, $D$17-P7, 0) -> 0 | R7: =P7+Q7 -> 18450000
B8: Delivery Date | D8: 45597 | G8: 45586 | I8: 2721.9 | J8: =I8-I7 -> -3.7 | K8: Closed | L8: =J8 -> -3.7 | M8: =$D$11*L8 -> -370000 | N8: =I8-$I$5 -> 43.3 | O8: =N8*$D$11 -> 4330000 | P8: =R7+M8 -> 18080000 | Q8: =IF(P8<$D$21, $D$17-P8, 0) -> 0 | R8: =P8+Q8 -> 18080000
B9: Contract Symbol | D9: GCZ4
B10: Position Type | D10: LONG
B11: Position (Oz) | D11: 100000
B12: Position (Contracts) | D12: =ROUND(D11/D6,0) -> 1000
B13: Contract Value, USD | D13: =D12*I5*D6 -> 267860000
B15: Margin
B16: Maintenance Margin (Contract) | D16: 11000
B17: Total Initial Margin, USD | D17: =D16*D18*D12 -> 13750000
B18: IBKR Margin Req. | D18: 1.25
B19: Initial Margin, % | D19: =D17/D13 -> 0.051332786
B20: Total, Maitenance Margin, USD | D20: =D16*D12 -> 11000000
B21: Margin Call Threshold | D21: =D20 -> 11000000
B22: Margin Calls in Period | D22: =COUNTIF(GoldTable[Margin Payment], ">0") -1 -> 0
A23: x

Sheet O1_NVDA
B1: NVDA OPTIONS | D1: https://finance.yahoo.com/quote/NVDA/
A3: x | B3: Details | G3: Date | H3: NVDA Stock | I3: Last Price | J3: Entry/Exit | K3: Daily +/- | L3: Cum. Total | M3: Current Account | N3: Margin Payment | O3: Curr. after Margin Payments
B4: Contract | G4: 45581 | H4: 135.72 | I4: 1.98
B5: Underlying | D5: NVIDIA Corp. | G5: 45582 | H5: 136.93 | I5: 2.09 | J5: Entry | K5: =NVDATable[[#This Row],[Last Price]]-I4 -> 0.11 | N5: =NVDATable[[#This Row],[Last Price]]*D6*D12 -> 4180000 | O5: =NVDATable[[#This Row],[Margin Payment]]+NVDATable[[#This Row],[Current Account]] -> 4180000
B6: Contract Size in Stock | D6: 100 | G6: 45583 | H6: 138 | I6: 2.04 | K6: =NVDATable[[#This Row],[Last Price]]-I5 -> -0.05 | L6: =(NVDATable[[#This Row],[Last Price]]-$I$5)*$D$12*$D$6 -> -100000 | M6: =O5+NVDATable[[#This Row],[Cum. Total]]-L5 -> 4080000 | N6: 0 | O6: =NVDATable[[#This Row],[Margin Payment]]+NVDATable[[#This Row],[Current Account]] -> 4080000
B7: Start Date | D7: 45582 | G7: 45586 | H7: 143.71 | I7: 5.1 | K7: =NVDATable[[#This Row],[Last Price]]-I6 -> 3.06 | L7: =(NVDATable[[#This Row],[Last Price]]-$I$5)*$D$12*$D$6 -> 6020000 | M7: =O6+NVDATable[[#This Row],[Cum. Total]]-L6 -> 10200000 | N7: 0 | O7: =NVDATable[[#This Row],[Margin Payment]]+NVDATable[[#This Row],[Current Account]] -> 10200000
B8: Expiry Date | D8: 45590 | G8: 45587 | H8: 143.53 | I8: 4.66 | J8: Exit | K8: =NVDATable[[#This Row],[Last Price]]-I7 -> -0.44 | L8: =(NVDATable[[#This Row],[Last Price]]-$I$5)*$D$12*$D$6 -> 5140000 | M8: =O7+NVDATable[[#This Row],[Cum. Total]]-L7 -> 9320000 | N8: 0 | O8: =NVDATable[[#This Row],[Margin Payment]]+NVDATable[[#This Row],[Current Account]] -> 9320000
B9: Contract Symbol | D9: CZGP
B10: Position Type | D10: LONG CALL
B11: Position (Stock) | D11: 2000000
B12: Position (Contracts) | D12: =D11/D6 -> 20000
B13: Contract Value, USD | D13: =D12*I5*D6 -> 4180000
B14: Strike Price | D14: 140
B16: Cash
B17: Cash Invested, USD | D17: =D12*$I$5*D6 -> 4180000
B18: Initial Margin, % | D18: -
B19: Total, Maitenance Margin, USD | D19: -
B20: Margin Call Threshold | D20: -
B21: Margin Calls in Period | D21: -

Sheet O2_TLT
B1: TLT OPTIONS | D1: https://finance.yahoo.com/quote/TLT/
A3: x | B3: Details | G3: Date | H3: TLT ETF | I3: Last Price | J3: Entry/Exit | K3: Daily +/- | L3: Cum. Total | M3: Current Account | N3: Margin Payment | O3: Curr. after Margin Payments
B4: Contract | G4: 45589 | H4: 92.66
B5: Underlying | D5: ISHARES 20+ YEAR TREASURY BOND | G5: 45590 | H5: 92.99 | I5: 4.17 | J5: Entry | K5: =TltTable[[#This Row],[Last Price]]-I4 -> 4.17 | N5: =D19 -> 10911000 | O5: =TltTable[[#This Row],[Margin Payment]]+TltTable[[#This Row],[Current Account]] -> 10911000
B6: Contract Size in Stock | D6: 100 | G6: 45598 | I6: 2.46 | J6: Exit | K6: =TltTable[[#This Row],[Last Price]]-I5 -> -1.71 | L6: =(TltTable[[#This Row],[Last Price]]-$I$5)*$D$12*$D$6+D17 -> 1230000 | M6: =O5+TltTable[[#This Row],[Cum. Total]]-L5 -> 12141000 | N6: 0 | O6: =TltTable[[#This Row],[Margin Payment]]+TltTable[[#This Row],[Current Account]] -> 12141000
B7: Start Date | D7: 45590
B8: Expiry Date | D8: 45747
B9: Contract Symbol | D9: PB7Z
B10: Position Type | D10: SHORT PUT
B11: Position (Stock) | D11: 500000
B12: Position (Contracts) | D12: =D11/D6 -> 5000
B13: Contract Value, USD | D13: =D12*I5*D6 -> 2085000
B14: Strike Price | D14: 93
B16: Margin
B17: Collected Premium, USD | D17: =D12*$I$5*D6 -> 2085000
B18: Margin per ETF share | D18: =I5+0.2*92.21- (93-92.21) -> 21.822
B19: Total Margin Required | D19: =D18*D11 -> 10911000
B20: Margin Call Threshold | D20: =D19 -> 10911000
B21: Margin Calls in Period | D21: -

Sheet O3_HOOD
B1: HOOD OPTIONS | D1: https://finance.yahoo.com/quote/HOOD/
A3: x | B3: Details | G3: Date | H3: HOOD Stock | I3: Last Price | J3: Entry/Exit | K3: Daily +/- | L3: Cum. Total | M3: Current Account | N3: Margin Payment | O3: Curr. after Margin Payments
